# 一、概念区分

> 异常分为两类，一类是Error，一类是Exception
>
> 为了使程序能正常运行，异常抛出的是编译时异常，之后若出现异常，再返回修改代码解决异常。

- **Error：**
  - Java虚拟机无法解决的严重问题。
  - 如`JVM`系统内部错误、资源耗尽等情况
  - 一般不编写针对性代码处理

```java
public class ErrorTest{
    public static void main(String args){
        //1.栈溢出：java.lang.StackOverflowError
        main(args);//main方法反复调用
        //2.堆溢出：java.lang.OutOfMemoryError
        Integer[] arr = new Integer[1024*1024*1024];
    }
}
```

- **（本文主要）Exception：**
  - 其他因编程错误或偶然因素导致的一般性问题
  - 如空指针访问，试图读取不存在文件等
  - 可以用针对性代码处理







# 二、常见异常-Exception





## 1、编译时异常（checked）

编译时报错，不生成字节码文件

### `IOException`

```java
public class ErrorTest{
    public static void main(String args){
        //1.
        File file = new File("hello.text");
        FileInputStream fis = new FileInputStream(file);
        
        int data = fis.read();//如果读到末尾，值为-1
        while(data!=-1){
            System.out.println((char)data);
            data = fis.read();
        }
        fis。close();
    }
}
```









## 2、运行时异常（unchecked）

运行时异常，生成字节码文件，运行时报错



### `NullPointerException`

空指针异常

```java
public class ErrorTest{
    public static void main(String args){
        //1.
     	int[] arr = null;
        System.out.println(arr[3]);//运行时报错
        //2.
        String str = "abc";
        str = null;
        System.out.println(str.charAt(0));//运行时报错//返回指定索引处的字段
    }
}
```



### `ArrayIndexOutOfBoundsException`

数组角标越界

```java
public class ErrorTest{
    public static void main(String args){
        //1.
     	int[] arr = new int[3];
        System.out.println(arr[3]);//运行时报错
        //2.
        String str = "abc";
        System.out.println(str.charAt(3));//运行时报错//String底层是Char型数组
    }
}
```



### `ClassCastExcetion`

类型转换异常

```java
public class ErrorTest{
    public static void main(String args){
        //1.
     	Object obj = new Date();
        String str = (String)obj;//运行时报错
    }
}
```





### `NumberFormatException`

数值类型错误

```java
public class ErrorTest{
    public static void main(String args){
        //1.
        String str = "abc123";
        int i = str.parseInt();//运行时报错
    }
}
```



### `InputMismatchException`

数值不匹配异常

```java
public class ErrorTest{
    public static void main(String args){
        //1.
        Scanner scanner = new Scanner(System.in);
        int score = scanner.nextInt();//输入值不为int型，则报错
    }
}
```





### `ArithmeticException`

算术运算错误

```java
public class ErrorTest{
    public static void main(String args){
        //1.
        int a = 5;
        int b = 0;
        System.out.println(a/b);//报错
    }
}
```



# 三、异常处理



异常处理——抓抛模型

- 过程一，“抛”
  - 程序在正常执行的过程中，一旦出现异常，就会在异常代码处生成一个异常类的对象
  - 并将此对象抛出
  - 一旦抛出，其后（try内）的代码不再执行



- 过程二，“抓”——异常处理的方式
  - 1、`try-catch-finally`
  - 2、`throws`



## 1、`try-catch-finally`

> 开发中由于运行时异常比较常见，也不知道会不会出现异常
>
> 所以通常不针对运行时异常编写`try-catch-finally`，只针对编译时出现的异常进行异常处理



`try-catch`的处理过程：

> 一旦try中代码执行发生异常，会生成一个异常对象。
>
> 异常常对象匹配到某一个`catch`时，就进入`catch`中进行异常处理。
>
> 一旦处理完成，就会跳出当前`try-catch`结构，继续执行其后的代码（`try`中未执行的代码不再执行）
>
> - 如果`catch`中也发生异常，则`try-catch`结构之后的代码不再执行




说明：

- catch中的异常类型自上而下匹配。

  如果catch中的异常类型存在子父类关系，则应子异常在上，父异常在下

- 在try中声明的变量，出了try结构，就不能再被调用。

  若想用，须在try结构之前作声明，然后在try结构中赋值
  
- `try-catch-finally`结构可以嵌套



`finally`的使用：

> 1、`finally`是可选的
>
> 2、`finally`中声明的是一定会被执行的代码。
>
> ​	  即使`try`中有`return`语句、`catch`中有`return`语句、`catch`中也报异常。
>
>   ​	`finally`都会执行



什么时候要用`finally`

> 像数据库的链接、输入输出流、网络编程`socket`等资源，JVM是不能自动回收的。
>
> 我们需要手动的进行资源的释放
>
> 此时资源的释放，就需要声明在`finally`中。（不论如何，必须释放）





常用的异常处理方式：

- `getMessage()`，返回的是一个String类型
- `printStackTrace`，打印处堆栈运行记录 



```java
try{
    //可能出现异常的代码
}catch(异常类型1 变量名1){
    //处理异常1 的方式
}catch(异常类型2 变量名2){
    //处理异常2 的方式
}catch(异常类型3 变量名3){
    //处理异常3 的方式
}
//finally可以不写
finally{
    //一定会执行的代码
}
```

```java
//try-catch使用
public class ErrorTest{
    public static void main(String args){
        
        String str = "abc123";
        try{
            int i = str.parseInt();//运行时报错
            
            System.out.println("hello-1");//不输出
            
        }catch(NumberFormatException e){
            //System.out.println("数值转换出现异常");
            
            //返回错误信息“For input...”
            System.out.println(e.getMessage());
            //返回堆栈记录
            e.printStackTrace();
        }
        System.out.println("hello-2");//输出
    }
}
```

```java
//finally使用一
public class ErrorTest{
    public static void main(String args){
        
        try{
            int[] arr = new int[10];         
            System.out.println(arr[10]);
            return 1;
            
        }catch(ArrayIndexOutOfBoundsException e){ 
            return 2;		
        }
        finally{
            System.out.println("我一定会被执行");
            return 3;
            /*
            关于 return:
            此时程序会返回 3
            如果注销return 3，则返回2
            */         
        }
    }
}
```

```java
//finally使用二
@Test
public void test2(){
    //为了在finally中使用fis变量，挪到try-catch结构外
    //初始化，赋值为null
    FileInputStream fis = null;
    
    try{
        File file = new File("hello.text");
        fis = new FileInputStream(file);
        
    }catch(FileNotFoundException e){
        e.printStackTrace();
    }catch(IOException e){
        e.printStackTrace();
    }finally{
        //fis还会出异常，再嵌套一层try-catch
        try{
            if(fis!=null)//防止空指针异常
            fis.close();
        }catch(IOException){
            e.printStackTrace());
        }
    }
}
```



## 2、`throws`



- `throws+异常类型`写在方法的声明处。指明此方法运行时可能会抛出的异常类型。

  一旦当方法体执行，出现异常，仍会在异常代码处生成一个异常类对象。

  此对象满足`throws`后的异常类型时，就会被抛出。异常后的代码不再执行



- `try-catch-finally`真正的将异常处理掉了
- `throws`只是把异常抛给方法的使用者，并没有真正的解决









```java
public class ExceptionTest{
    public static void main(String[] args){
        
        //最终都要用try-catch进行异常解决
        try{
            method2();
        }catch(IOException e){
            e.printStackTrace();
        }
    }
    
    //IOException 是 FileNotFoundException的父类
    public static void method2() throws IOException{
        method1();
    }
    
    public static void method1() throws IOException,FileNotFoundException{
        File file = new File("hello.text");
        fis = new FileInputStream(file);//报错，文件不存在
    }
}
```





### 方法重写抛出异常的规则



方法重写规则之一：

- 子类重写的方法抛出的异常，不大于父类被重写方法抛出的异常类型

- 父类方法要是没有抛异常，子类方法也不可抛异常



使用多态时，如果子类方法抛出的异常超过父类被重写的方法，那么就`catch`不住，出现问题。

相反，要是子类抛出的异常小于父类的，那么依然可以`catch`主。

```java
public class OverrideTest{
    public static void main(String[] args){}
    public void methodNot(SuperClass s){
        try{
            s.method();
        }catch(IOexception e){
            e.printStackTrace();
        }
    }
}

public class SuperClass{
    public void method() throws IOException{}
}

public class SubClass extends SuperClass{    
    public void method() throws FileNotFoundException{}
}
```



## 3、选择哪种处理方式？



- 如果父类中被重写的方法没有`throws`抛异常，则子类重写的方法也不能使用`throws`。

  意味着，子类重写的方法要是有异常，必须使用`try-catch-finally`

- 执行的方法A中，先后又调用了另外几个方法，这几个方法是递进关系执行的。我们建议这几个方法使用`throws`的方式进行处理。而方法A使用`try-catch-finally`d的方法进行处理
  - 因为另外几个方法可能存在变量依赖的关系，如果前面的一个方法执行异常，那么后面的方法的执行也必定有问题。
  - 使用`try-catch-finally`的话，出现异常后，会继续往下执行代码，但这样之后的方法执行出的结果也必定是错误的。所以使用`throws`方法，出现异常后中断执行。





## 4、手动抛出异常

> 相当于python的`raise`

- 关键字-`throw`



```java
public void show(){
    try{
        regist(-1001);
    }catch(RuntimeException e){
        System.out.println(e.getMessage());//输出"您输入的数据非法"
    } 
}

public void regist(int id){
    if (id>0){
        this.id = id;
    }else{
        //将“您输入的数据非法”赋值给message
        //getMessage()方法可以获取到"您输入的数据非法"
        throw new RuntimeException("您输入的数据非法");  
    }
}
```

